<sdf version='1.6'>
  <world name='default'>
    <model name='ground_plane'>
      <static>1</static>
      <link name='link'>
        <collision name='collision'>
          <geometry>
            <plane>
              <normal>0 0 1</normal>
              <size>100 100</size>
            </plane>
          </geometry>
          <surface>
            <contact>
              <collide_bitmask>65535</collide_bitmask>
              <ode/>
            </contact>
            <friction>
              <ode>
                <mu>100</mu>
                <mu2>50</mu2>
              </ode>
              <torsional>
                <ode/>
              </torsional>
            </friction>
            <bounce/>
          </surface>
          <max_contacts>10</max_contacts>
        </collision>
        <visual name='visual'>
          <cast_shadows>0</cast_shadows>
          <geometry>
            <plane>
              <normal>0 0 1</normal>
              <size>100 100</size>
            </plane>
          </geometry>
          <material>
            <script>
              <uri>file://media/materials/scripts/gazebo.material</uri>
              <name>Gazebo/Grey</name>
            </script>
          </material>
        </visual>
        <self_collide>0</self_collide>
        <enable_wind>0</enable_wind>
        <kinematic>0</kinematic>
      </link>
    </model>
    <light name='sun' type='directional'>
      <cast_shadows>1</cast_shadows>
      <pose frame=''>0 0 10 0 -0 0</pose>
      <diffuse>0.8 0.8 0.8 1</diffuse>
      <specular>0.2 0.2 0.2 1</specular>
      <attenuation>
        <range>1000</range>
        <constant>0.9</constant>
        <linear>0.01</linear>
        <quadratic>0.001</quadratic>
      </attenuation>
      <direction>-0.5 0.1 -0.9</direction>
    </light>
    <gravity>0 0 -9.8</gravity>
    <magnetic_field>6e-06 2.3e-05 -4.2e-05</magnetic_field>
    <atmosphere type='adiabatic'/>
    <physics name='default_physics' default='0' type='ode'>
      <max_step_size>0.001</max_step_size>
      <real_time_factor>1</real_time_factor>
      <real_time_update_rate>1000</real_time_update_rate>
    </physics>
    <scene>
      <ambient>0.4 0.4 0.4 1</ambient>
      <background>0.7 0.7 0.7 1</background>
      <shadows>1</shadows>
    </scene>
    <audio>
      <device>default</device>
    </audio>
    <wind/>
    <spherical_coordinates>
      <surface_model>EARTH_WGS84</surface_model>
      <latitude_deg>0</latitude_deg>
      <longitude_deg>0</longitude_deg>
      <elevation>0</elevation>
      <heading_deg>0</heading_deg>
    </spherical_coordinates>
    <model name='outr'>
      <link name='chassis'>
        <pose frame=''>0 0 0 0 -0 0</pose>
        <inertial>
          <pose frame=''>0 0 0.1 0 -0 0</pose>
          <mass>10</mass>
          <inertia>
            <ixx>0.5</ixx>
            <ixy>0</ixy>
            <ixz>0</ixz>
            <iyy>1</iyy>
            <iyz>0</iyz>
            <izz>0.1</izz>
          </inertia>
        </inertial>
        <collision name='chassis_fixed_joint_lump__collision_collision'>
          <pose frame=''>0 0 0 0 -0 0</pose>
          <geometry>
            <mesh>
              <scale>1 1 1</scale>
              <uri>/home/ensar/catkin_ws/src/outr_description/urdf/outr.dae</uri>
            </mesh>
          </geometry>
          <max_contacts>10</max_contacts>
          <surface>
            <contact>
              <ode/>
            </contact>
            <bounce/>
            <friction>
              <torsional>
                <ode/>
              </torsional>
              <ode/>
            </friction>
          </surface>
        </collision>
        <collision name='chassis_fixed_joint_lump__caster_collision_collision_1'>
          <pose frame=''>-0.15 0 -0.05 0 -0 0</pose>
          <geometry>
            <sphere>
              <radius>0.05</radius>
            </sphere>
          </geometry>
          <max_contacts>10</max_contacts>
          <surface>
            <contact>
              <ode/>
            </contact>
            <bounce/>
            <friction>
              <torsional>
                <ode/>
              </torsional>
              <ode/>
            </friction>
          </surface>
        </collision>
        <visual name='chassis_visual_visual'>
          <pose frame=''>0 0 0 0 -0 0</pose>
          <geometry>
            <mesh>
              <scale>1 1 1</scale>
              <uri>/home/ensar/catkin_ws/src/outr_description/urdf/outr.dae</uri>
            </mesh>
          </geometry>
        </visual>
        <visual name='chassis_fixed_joint_lump__caster_visual_visual_1'>
          <pose frame=''>-0.15 0 -0.05 0 -0 0</pose>
          <geometry>
            <sphere>
              <radius>0.05</radius>
            </sphere>
          </geometry>
        </visual>
        <self_collide>0</self_collide>
        <enable_wind>0</enable_wind>
        <kinematic>0</kinematic>
      </link>
      <link name='left_wheel'>
        <pose frame=''>0.1 0.15 0 0 -0 0</pose>
        <inertial>
          <pose frame=''>0 0 0 -0 1.5707 1.5707</pose>
          <mass>5</mass>
          <inertia>
            <ixx>1</ixx>
            <ixy>0</ixy>
            <ixz>0</ixz>
            <iyy>1</iyy>
            <iyz>0</iyz>
            <izz>1</izz>
          </inertia>
        </inertial>
        <collision name='left_wheel_fixed_joint_lump__collision_collision'>
          <pose frame=''>0 0 0 3.14159 1.57079 -1.57089</pose>
          <geometry>
            <cylinder>
              <length>0.05</length>
              <radius>0.1</radius>
            </cylinder>
          </geometry>
          <max_contacts>10</max_contacts>
          <surface>
            <contact>
              <ode/>
            </contact>
            <bounce/>
            <friction>
              <torsional>
                <ode/>
              </torsional>
              <ode/>
            </friction>
          </surface>
        </collision>
        <visual name='left_wheel_visual_visual'>
          <pose frame=''>0 0 0 3.14159 1.57079 -1.57089</pose>
          <geometry>
            <cylinder>
              <length>0.05</length>
              <radius>0.1</radius>
            </cylinder>
          </geometry>
        </visual>
        <self_collide>0</self_collide>
        <enable_wind>0</enable_wind>
        <kinematic>0</kinematic>
      </link>
      <joint name='left_wheel_hinge' type='revolute'>
        <child>left_wheel</child>
        <parent>chassis</parent>
        <axis>
          <xyz>0 1 0</xyz>
          <limit>
            <lower>-1e+16</lower>
            <upper>1e+16</upper>
          </limit>
          <dynamics>
            <spring_reference>0</spring_reference>
            <spring_stiffness>0</spring_stiffness>
          </dynamics>
          <use_parent_model_frame>1</use_parent_model_frame>
        </axis>
      </joint>
      <link name='right_wheel'>
        <pose frame=''>0.1 -0.15 0 0 -0 0</pose>
        <inertial>
          <pose frame=''>0 0 0 -0 1.5707 1.5707</pose>
          <mass>5</mass>
          <inertia>
            <ixx>1</ixx>
            <ixy>0</ixy>
            <ixz>0</ixz>
            <iyy>1</iyy>
            <iyz>0</iyz>
            <izz>1</izz>
          </inertia>
        </inertial>
        <collision name='right_wheel_fixed_joint_lump__collision_collision'>
          <pose frame=''>0 0 0 3.14159 1.57079 -1.57089</pose>
          <geometry>
            <cylinder>
              <length>0.05</length>
              <radius>0.1</radius>
            </cylinder>
          </geometry>
          <max_contacts>10</max_contacts>
          <surface>
            <contact>
              <ode/>
            </contact>
            <bounce/>
            <friction>
              <torsional>
                <ode/>
              </torsional>
              <ode/>
            </friction>
          </surface>
        </collision>
        <visual name='right_wheel_visual_visual'>
          <pose frame=''>0 0 0 3.14159 1.57079 -1.57089</pose>
          <geometry>
            <cylinder>
              <length>0.05</length>
              <radius>0.1</radius>
            </cylinder>
          </geometry>
        </visual>
        <self_collide>0</self_collide>
        <enable_wind>0</enable_wind>
        <kinematic>0</kinematic>
      </link>
      <joint name='right_wheel_hinge' type='revolute'>
        <child>right_wheel</child>
        <parent>chassis</parent>
        <axis>
          <xyz>0 1 0</xyz>
          <limit>
            <lower>-1e+16</lower>
            <upper>1e+16</upper>
          </limit>
          <dynamics>
            <spring_reference>0</spring_reference>
            <spring_stiffness>0</spring_stiffness>
          </dynamics>
          <use_parent_model_frame>1</use_parent_model_frame>
        </axis>
      </joint>
      <static>0</static>
      <plugin name='differential_drive_controller' filename='libgazebo_ros_diff_drive.so'>
        <legacyMode>0</legacyMode>
        <alwaysOn>1</alwaysOn>
        <updateRate>20</updateRate>
        <leftJoint>left_wheel_hinge</leftJoint>
        <rightJoint>right_wheel_hinge</rightJoint>
        <wheelSeparation>0.4</wheelSeparation>
        <wheelDiameter>0.1</wheelDiameter>
        <torque>20</torque>
        <commandTopic>cmd_vel</commandTopic>
        <odometryTopic>odom</odometryTopic>
        <odometryFrame>odom</odometryFrame>
        <robotBaseFrame>chassis</robotBaseFrame>
        <robotNamespace>/</robotNamespace>
      </plugin>
      <pose frame=''>0 0 0 0 -0 0</pose>
    </model>
    <model name='willowgarage'>
      <static>1</static>
      <pose frame=''>-27.5682 -35.8947 0 0 -0 0</pose>
      <link name='walls'>
        <collision name='collision'>
          <geometry>
            <mesh>
              <uri>model://willowgarage/meshes/willowgarage_collision.dae</uri>
            </mesh>
          </geometry>
          <max_contacts>10</max_contacts>
          <surface>
            <contact>
              <ode/>
            </contact>
            <bounce/>
            <friction>
              <torsional>
                <ode/>
              </torsional>
              <ode/>
            </friction>
          </surface>
        </collision>
        <visual name='visual'>
          <geometry>
            <mesh>
              <uri>model://willowgarage/meshes/willowgarage_visual.dae</uri>
            </mesh>
          </geometry>
          <cast_shadows>0</cast_shadows>
        </visual>
        <self_collide>0</self_collide>
        <enable_wind>0</enable_wind>
        <kinematic>0</kinematic>
      </link>
    </model>
    <state world_name='default'>
      <sim_time>122 756000000</sim_time>
      <real_time>146 466666664</real_time>
      <wall_time>1588110403 196482754</wall_time>
      <iterations>122756</iterations>
      <model name='ground_plane'>
        <pose frame=''>0 0 0 0 -0 0</pose>
        <scale>1 1 1</scale>
        <link name='link'>
          <pose frame=''>0 0 0 0 -0 0</pose>
          <velocity>0 0 0 0 -0 0</velocity>
          <acceleration>0 0 0 0 -0 0</acceleration>
          <wrench>0 0 0 0 -0 0</wrench>
        </link>
      </model>
      <model name='outr'>
        <pose frame=''>0.004223 -1.8e-05 0.099992 0 -6e-06 0.000976</pose>
        <scale>1 1 1</scale>
        <link name='chassis'>
          <pose frame=''>0.004223 -1.8e-05 0.099992 0 -6e-06 0.000976</pose>
          <velocity>-0.000294 0.000492 -0.008055 -0.004762 -0.00315 -0.000191</velocity>
          <acceleration>0.014184 0.015294 -9.78487 0.051785 -0.032571 -0.123126</acceleration>
          <wrench>0.14184 0.152938 -97.8487 0 -0 0</wrench>
        </link>
        <link name='left_wheel'>
          <pose frame=''>0.104076 0.15008 0.099993 0 -0.005123 0.000976</pose>
          <velocity>-0.000256 0.000461 -0.00843 -0.004767 -0.00315 -0.000204</velocity>
          <acceleration>-0.010832 0.000297 -9.80879 -0.006417 -0.003922 0.081438</acceleration>
          <wrench>-0.054158 0.001486 -49.044 0 -0 0</wrench>
        </link>
        <link name='right_wheel'>
          <pose frame=''>0.104369 -0.14992 0.099993 1e-06 -0.001888 0.000976</pose>
          <velocity>-0.000332 0.000447 -0.007063 -0.004797 -0.00315 -0.000263</velocity>
          <acceleration>-0.017536 -0.030885 -9.82148 -0.013712 0.007216 -0.048809</acceleration>
          <wrench>-0.087682 -0.154424 -49.1074 0 -0 0</wrench>
        </link>
      </model>
      <model name='willowgarage'>
        <pose frame=''>-27.5682 -35.8947 0 0 -0 0</pose>
        <scale>1 1 1</scale>
        <link name='walls'>
          <pose frame=''>-27.5682 -35.8947 0 0 -0 0</pose>
          <velocity>0 0 0 0 -0 0</velocity>
          <acceleration>0 0 0 0 -0 0</acceleration>
          <wrench>0 0 0 0 -0 0</wrench>
        </link>
      </model>
      <light name='sun'>
        <pose frame=''>0 0 10 0 -0 0</pose>
      </light>
    </state>
    <gui fullscreen='0'>
      <camera name='user_camera'>
        <pose frame=''>17.4249 -5.86813 124.85 -0 1.45564 2.71219</pose>
        <view_controller>orbit</view_controller>
        <projection_type>perspective</projection_type>
      </camera>
    </gui>
  </world>
</sdf>
